Traceback (most recent call last):
  File "/home/jed/cu/nc/VENV/lib/python3.10/site-packages/jupyter_cache/executors/utils.py", line 51, in single_nb_execution
    executenb(
  File "/home/jed/cu/nc/VENV/lib/python3.10/site-packages/nbclient/client.py", line 1093, in execute
    return NotebookClient(nb=nb, resources=resources, km=km, **kwargs).execute()
  File "/home/jed/cu/nc/VENV/lib/python3.10/site-packages/nbclient/util.py", line 84, in wrapped
    return just_run(coro(*args, **kwargs))
  File "/home/jed/cu/nc/VENV/lib/python3.10/site-packages/nbclient/util.py", line 62, in just_run
    return loop.run_until_complete(coro)
  File "/usr/lib/python3.10/asyncio/base_events.py", line 641, in run_until_complete
    return future.result()
  File "/home/jed/cu/nc/VENV/lib/python3.10/site-packages/nbclient/client.py", line 559, in async_execute
    await self.async_execute_cell(
  File "/home/jed/cu/nc/VENV/lib/python3.10/site-packages/nbclient/client.py", line 854, in async_execute_cell
    self._check_raise_for_error(cell, exec_reply)
  File "/home/jed/cu/nc/VENV/lib/python3.10/site-packages/nbclient/client.py", line 756, in _check_raise_for_error
    raise CellExecutionError.from_cell_and_msg(cell, exec_reply_content)
nbclient.exceptions.CellExecutionError: An error occurred while executing the following cell:
------------------
newton(f, fp, 3*pi/2; verbose=true)
------------------

DomainError with Inf:
cos(x) is only defined for finite x.

Stacktrace:
 [1] cos_domain_error(x::Float64)
   @ Base.Math ./special/trig.jl:97
 [2] cos(x::Float64)
   @ Base.Math ./special/trig.jl:108
 [3] f
   @ ./In[8]:16 [inlined]
 [4] newton(f::typeof(f), fp::typeof(fp), x0::Float64; tol::Float64, verbose::Bool)
   @ Main ./In[8]:4
 [5] top-level scope
   @ In[9]:1
 [6] eval
   @ ./boot.jl:373 [inlined]
 [7] include_string(mapexpr::typeof(REPL.softscope), mod::Module, code::String, filename::String)
   @ Base ./loading.jl:1196
LoadError: DomainError with Inf:
cos(x) is only defined for finite x.

