Traceback (most recent call last):
  File "/home/jed/cu/nc/VENV/lib/python3.10/site-packages/jupyter_cache/executors/utils.py", line 51, in single_nb_execution
    executenb(
  File "/home/jed/cu/nc/VENV/lib/python3.10/site-packages/nbclient/client.py", line 1256, in execute
    return NotebookClient(nb=nb, resources=resources, km=km, **kwargs).execute()
  File "/home/jed/cu/nc/VENV/lib/python3.10/site-packages/nbclient/util.py", line 87, in wrapped
    return just_run(coro(*args, **kwargs))
  File "/home/jed/cu/nc/VENV/lib/python3.10/site-packages/nbclient/util.py", line 62, in just_run
    return loop.run_until_complete(coro)
  File "/usr/lib/python3.10/asyncio/base_events.py", line 649, in run_until_complete
    return future.result()
  File "/home/jed/cu/nc/VENV/lib/python3.10/site-packages/nbclient/client.py", line 694, in async_execute
    await self.async_execute_cell(
  File "/home/jed/cu/nc/VENV/lib/python3.10/site-packages/nbclient/client.py", line 1012, in async_execute_cell
    await self._check_raise_for_error(cell, cell_index, exec_reply)
  File "/home/jed/cu/nc/VENV/lib/python3.10/site-packages/nbclient/client.py", line 906, in _check_raise_for_error
    raise CellExecutionError.from_cell_and_msg(cell, exec_reply_content)
nbclient.exceptions.CellExecutionError: An error occurred while executing the following cell:
------------------
myexp(-30, 1000), exp(-30)
------------------

UndefVarError: myexp not defined

Stacktrace:
 [1] top-level scope
   @ In[6]:1
 [2] eval
   @ ./boot.jl:368 [inlined]
 [3] include_string(mapexpr::typeof(REPL.softscope), mod::Module, code::String, filename::String)
   @ Base ./loading.jl:1428
LoadError: UndefVarError: myexp not defined

