Traceback (most recent call last):
  File "/home/jed/cu/nc-25f/class/VENV/lib/python3.13/site-packages/jupyter_core/utils/__init__.py", line 154, in wrapped
    asyncio.get_running_loop()
    ~~~~~~~~~~~~~~~~~~~~~~~~^^
RuntimeError: no running event loop

During handling of the above exception, another exception occurred:

Traceback (most recent call last):
  File "/home/jed/cu/nc-25f/class/VENV/lib/python3.13/site-packages/jupyter_cache/executors/utils.py", line 58, in single_nb_execution
    executenb(
    ~~~~~~~~~^
        nb,
        ^^^
    ...<4 lines>...
        **kwargs,
        ^^^^^^^^^
    )
    ^
  File "/home/jed/cu/nc-25f/class/VENV/lib/python3.13/site-packages/nbclient/client.py", line 1319, in execute
    return NotebookClient(nb=nb, resources=resources, km=km, **kwargs).execute()
           ~~~~~~~~~~~~~~~~~~~~~~~~~~~~~~~~~~~~~~~~~~~~~~~~~~~~~~~~~~~~~~~~~~~^^
  File "/home/jed/cu/nc-25f/class/VENV/lib/python3.13/site-packages/jupyter_core/utils/__init__.py", line 158, in wrapped
    return loop.run_until_complete(inner)
           ~~~~~~~~~~~~~~~~~~~~~~~^^^^^^^
  File "/usr/lib/python3.13/asyncio/base_events.py", line 725, in run_until_complete
    return future.result()
           ~~~~~~~~~~~~~^^
  File "/home/jed/cu/nc-25f/class/VENV/lib/python3.13/site-packages/nbclient/client.py", line 709, in async_execute
    await self.async_execute_cell(
        cell, index, execution_count=self.code_cells_executed + 1
    )
  File "/home/jed/cu/nc-25f/class/VENV/lib/python3.13/site-packages/nbclient/client.py", line 1062, in async_execute_cell
    await self._check_raise_for_error(cell, cell_index, exec_reply)
  File "/home/jed/cu/nc-25f/class/VENV/lib/python3.13/site-packages/nbclient/client.py", line 918, in _check_raise_for_error
    raise CellExecutionError.from_cell_and_msg(cell, exec_reply_content)
nbclient.exceptions.CellExecutionError: An error occurred while executing the following cell:
------------------
using FastTransforms

n = 64; m = 62
x = 0:n-1
f = exp.(2im * pi * m * x / n)
plot(x, real.(f), ylim=(-1.1, 1.1), marker=:circle)
------------------


ArgumentError: Package FastTransforms not found in current path.
- Run `import Pkg; Pkg.add("FastTransforms")` to install the FastTransforms package.

Stacktrace:
 [1] macro expansion
   @ ./loading.jl:2296 [inlined]
 [2] macro expansion
   @ ./lock.jl:273 [inlined]
 [3] __require(into::Module, mod::Symbol)
   @ Base ./loading.jl:2271
 [4] #invoke_in_world#3
   @ ./essentials.jl:1089 [inlined]
 [5] invoke_in_world
   @ ./essentials.jl:1086 [inlined]
 [6] require(into::Module, mod::Symbol)
   @ Base ./loading.jl:2260

